2025-04-28 01:06:26,656 - module1 - INFO - This is a log message from module1
2025-04-28 01:06:26,740 - helper.DBSchema_Handler - INFO - Database Connection test Passed, Horray ...
2025-04-28 01:10:37,263 - module1 - INFO - This is a log message from module1
2025-04-28 01:10:37,349 - helper.DBSchema_Handler - INFO - Database Connection test Passed, Horray ...
2025-04-28 01:10:52,203 - __main__ - INFO - Number of records loaded to the database 478333 in 14.852625608444214 seconds
2025-04-28 01:12:18,568 - module1 - INFO - This is a log message from module1
2025-04-28 01:12:18,569 - __main__ - INFO - Data Extraction Started
2025-04-28 01:13:13,966 - __main__ - INFO - Data Extraction done now dumping to result.json under output directory specefied in Config.cfg
2025-04-28 01:13:16,086 - __main__ - INFO - whole extraction done using lxml in 57 second for 478333 line.
2025-04-28 01:13:16,286 - helper.DBSchema_Handler - INFO - Database Connection test Passed, Horray ...
2025-04-28 01:13:31,577 - __main__ - INFO - Number of records loaded to the database 478333 in 15.290906429290771 seconds
2025-04-28 01:18:41,006 - module1 - INFO - This is a log message from module1
2025-04-28 01:18:41,007 - __main__ - INFO - Data Extraction Started
2025-04-28 01:18:48,919 - __main__ - INFO - Database Connection test Passed, Horray ...
2025-04-28 01:19:20,478 - __main__ - INFO - Database Connection test Passed, Horray ...
2025-04-28 01:20:28,389 - __main__ - INFO - Database Connection test Passed, Horray ...
2025-04-28 01:20:48,542 - __main__ - INFO - Database Connection test Passed, Horray ...
2025-04-28 01:21:33,667 - __main__ - INFO - Database Connection test Passed, Horray ...
2025-04-28 01:21:33,705 - __main__ - ERROR - Cant add default group to the table, this is normal if the user group already exist for Details: (psycopg2.errors.UniqueViolation) duplicate key value violates unique constraint "groups_authority_pkey"
DETAIL:  Key (id)=(1) already exists.

[SQL: INSERT INTO groups_authority (id, groupname, group_authority) VALUES (%(id)s, %(groupname)s, %(group_authority)s)]
[parameters: {'id': 1, 'groupname': 'Default', 'group_authority': 0}]
(Background on this error at: https://sqlalche.me/e/20/gkpj)
Traceback (most recent call last):
  File "C:\Users\fadyz\Desktop\Personal\python-mess\SRS\.srs_algorithm\Lib\site-packages\sqlalchemy\engine\base.py", line 1964, in _exec_single_context
    self.dialect.do_execute(
  File "C:\Users\fadyz\Desktop\Personal\python-mess\SRS\.srs_algorithm\Lib\site-packages\sqlalchemy\engine\default.py", line 945, in do_execute
    cursor.execute(statement, parameters)
psycopg2.errors.UniqueViolation: duplicate key value violates unique constraint "groups_authority_pkey"
DETAIL:  Key (id)=(1) already exists.


The above exception was the direct cause of the following exception:

Traceback (most recent call last):
  File "c:\Users\fadyz\Desktop\Personal\python-mess\SRS\helper\DBSchema_Handler.py", line 93, in createschema
    conn.execute(insert(self.groups_authority).values(id=1, groupname='Default',group_authority=0))
  File "C:\Users\fadyz\Desktop\Personal\python-mess\SRS\.srs_algorithm\Lib\site-packages\sqlalchemy\engine\base.py", line 1416, in execute
    return meth(
           ^^^^^
  File "C:\Users\fadyz\Desktop\Personal\python-mess\SRS\.srs_algorithm\Lib\site-packages\sqlalchemy\sql\elements.py", line 523, in _execute_on_connection
    return connection._execute_clauseelement(
           ^^^^^^^^^^^^^^^^^^^^^^^^^^^^^^^^^^
  File "C:\Users\fadyz\Desktop\Personal\python-mess\SRS\.srs_algorithm\Lib\site-packages\sqlalchemy\engine\base.py", line 1638, in _execute_clauseelement
    ret = self._execute_context(
          ^^^^^^^^^^^^^^^^^^^^^^
  File "C:\Users\fadyz\Desktop\Personal\python-mess\SRS\.srs_algorithm\Lib\site-packages\sqlalchemy\engine\base.py", line 1843, in _execute_context
    return self._exec_single_context(
           ^^^^^^^^^^^^^^^^^^^^^^^^^^
  File "C:\Users\fadyz\Desktop\Personal\python-mess\SRS\.srs_algorithm\Lib\site-packages\sqlalchemy\engine\base.py", line 1983, in _exec_single_context
    self._handle_dbapi_exception(
  File "C:\Users\fadyz\Desktop\Personal\python-mess\SRS\.srs_algorithm\Lib\site-packages\sqlalchemy\engine\base.py", line 2352, in _handle_dbapi_exception
    raise sqlalchemy_exception.with_traceback(exc_info[2]) from e
  File "C:\Users\fadyz\Desktop\Personal\python-mess\SRS\.srs_algorithm\Lib\site-packages\sqlalchemy\engine\base.py", line 1964, in _exec_single_context
    self.dialect.do_execute(
  File "C:\Users\fadyz\Desktop\Personal\python-mess\SRS\.srs_algorithm\Lib\site-packages\sqlalchemy\engine\default.py", line 945, in do_execute
    cursor.execute(statement, parameters)
sqlalchemy.exc.IntegrityError: (psycopg2.errors.UniqueViolation) duplicate key value violates unique constraint "groups_authority_pkey"
DETAIL:  Key (id)=(1) already exists.

[SQL: INSERT INTO groups_authority (id, groupname, group_authority) VALUES (%(id)s, %(groupname)s, %(group_authority)s)]
[parameters: {'id': 1, 'groupname': 'Default', 'group_authority': 0}]
(Background on this error at: https://sqlalche.me/e/20/gkpj)
2025-04-28 01:23:35,863 - __main__ - INFO - Database Connection test Passed, Horray ...
2025-04-28 01:23:46,635 - module1 - INFO - This is a log message from module1
2025-04-28 01:23:46,636 - __main__ - INFO - Data Extraction Started
2025-04-28 01:24:41,528 - __main__ - INFO - Data Extraction done now dumping to result.json under output directory specefied in Config.cfg
2025-04-28 01:24:43,414 - __main__ - INFO - whole extraction done using lxml in 56 second for 478333 line.
2025-04-28 01:24:43,589 - helper.DBSchema_Handler - INFO - Database Connection test Passed, Horray ...
2025-04-28 01:25:00,598 - __main__ - INFO - Number of records loaded to the database 478333 in 17.0094256401062 seconds
2025-04-28 11:12:16,337 - module1 - INFO - This is a log message from module1
2025-04-28 11:12:16,370 - passlib.registry - DEBUG - registered 'pbkdf2_sha256' handler: <class 'passlib.handlers.pbkdf2.pbkdf2_sha256'>
2025-04-28 11:12:37,593 - helper.DBSchema_Handler - ERROR - Database Connection Faile for Deatils:(psycopg2.OperationalError) connection to server at "1.1.1.142", port 5432 failed: Connection timed out (0x0000274C/10060)
	Is the server running on that host and accepting TCP/IP connections?

(Background on this error at: https://sqlalche.me/e/20/e3q8)
Traceback (most recent call last):
  File "C:\Users\fadyz\Desktop\Personal\python-mess\SRS\.srs_algorithm\Lib\site-packages\sqlalchemy\engine\base.py", line 146, in __init__
    self._dbapi_connection = engine.raw_connection()
                             ^^^^^^^^^^^^^^^^^^^^^^^
  File "C:\Users\fadyz\Desktop\Personal\python-mess\SRS\.srs_algorithm\Lib\site-packages\sqlalchemy\engine\base.py", line 3298, in raw_connection
    return self.pool.connect()
           ^^^^^^^^^^^^^^^^^^^
  File "C:\Users\fadyz\Desktop\Personal\python-mess\SRS\.srs_algorithm\Lib\site-packages\sqlalchemy\pool\base.py", line 449, in connect
    return _ConnectionFairy._checkout(self)
           ^^^^^^^^^^^^^^^^^^^^^^^^^^^^^^^^
  File "C:\Users\fadyz\Desktop\Personal\python-mess\SRS\.srs_algorithm\Lib\site-packages\sqlalchemy\pool\base.py", line 1264, in _checkout
    fairy = _ConnectionRecord.checkout(pool)
            ^^^^^^^^^^^^^^^^^^^^^^^^^^^^^^^^
  File "C:\Users\fadyz\Desktop\Personal\python-mess\SRS\.srs_algorithm\Lib\site-packages\sqlalchemy\pool\base.py", line 713, in checkout
    rec = pool._do_get()
          ^^^^^^^^^^^^^^
  File "C:\Users\fadyz\Desktop\Personal\python-mess\SRS\.srs_algorithm\Lib\site-packages\sqlalchemy\pool\impl.py", line 179, in _do_get
    with util.safe_reraise():
  File "C:\Users\fadyz\Desktop\Personal\python-mess\SRS\.srs_algorithm\Lib\site-packages\sqlalchemy\util\langhelpers.py", line 146, in __exit__
    raise exc_value.with_traceback(exc_tb)
  File "C:\Users\fadyz\Desktop\Personal\python-mess\SRS\.srs_algorithm\Lib\site-packages\sqlalchemy\pool\impl.py", line 177, in _do_get
    return self._create_connection()
           ^^^^^^^^^^^^^^^^^^^^^^^^^
  File "C:\Users\fadyz\Desktop\Personal\python-mess\SRS\.srs_algorithm\Lib\site-packages\sqlalchemy\pool\base.py", line 390, in _create_connection
    return _ConnectionRecord(self)
           ^^^^^^^^^^^^^^^^^^^^^^^
  File "C:\Users\fadyz\Desktop\Personal\python-mess\SRS\.srs_algorithm\Lib\site-packages\sqlalchemy\pool\base.py", line 675, in __init__
    self.__connect()
  File "C:\Users\fadyz\Desktop\Personal\python-mess\SRS\.srs_algorithm\Lib\site-packages\sqlalchemy\pool\base.py", line 901, in __connect
    with util.safe_reraise():
  File "C:\Users\fadyz\Desktop\Personal\python-mess\SRS\.srs_algorithm\Lib\site-packages\sqlalchemy\util\langhelpers.py", line 146, in __exit__
    raise exc_value.with_traceback(exc_tb)
  File "C:\Users\fadyz\Desktop\Personal\python-mess\SRS\.srs_algorithm\Lib\site-packages\sqlalchemy\pool\base.py", line 897, in __connect
    self.dbapi_connection = connection = pool._invoke_creator(self)
                                         ^^^^^^^^^^^^^^^^^^^^^^^^^^
  File "C:\Users\fadyz\Desktop\Personal\python-mess\SRS\.srs_algorithm\Lib\site-packages\sqlalchemy\engine\create.py", line 646, in connect
    return dialect.connect(*cargs, **cparams)
           ^^^^^^^^^^^^^^^^^^^^^^^^^^^^^^^^^^
  File "C:\Users\fadyz\Desktop\Personal\python-mess\SRS\.srs_algorithm\Lib\site-packages\sqlalchemy\engine\default.py", line 625, in connect
    return self.loaded_dbapi.connect(*cargs, **cparams)  # type: ignore[no-any-return]  # NOQA: E501
           ^^^^^^^^^^^^^^^^^^^^^^^^^^^^^^^^^^^^^^^^^^^^
  File "C:\Users\fadyz\Desktop\Personal\python-mess\SRS\.srs_algorithm\Lib\site-packages\psycopg2\__init__.py", line 122, in connect
    conn = _connect(dsn, connection_factory=connection_factory, **kwasync)
           ^^^^^^^^^^^^^^^^^^^^^^^^^^^^^^^^^^^^^^^^^^^^^^^^^^^^^^^^^^^^^^^
psycopg2.OperationalError: connection to server at "1.1.1.142", port 5432 failed: Connection timed out (0x0000274C/10060)
	Is the server running on that host and accepting TCP/IP connections?


The above exception was the direct cause of the following exception:

Traceback (most recent call last):
  File "c:\Users\fadyz\Desktop\Personal\python-mess\SRS\helper\DBSchema_Handler.py", line 41, in create_alchemy_engine
    with engine.connect() as conn:
         ^^^^^^^^^^^^^^^^
  File "C:\Users\fadyz\Desktop\Personal\python-mess\SRS\.srs_algorithm\Lib\site-packages\sqlalchemy\engine\base.py", line 3274, in connect
    return self._connection_cls(self)
           ^^^^^^^^^^^^^^^^^^^^^^^^^^
  File "C:\Users\fadyz\Desktop\Personal\python-mess\SRS\.srs_algorithm\Lib\site-packages\sqlalchemy\engine\base.py", line 148, in __init__
    Connection._handle_dbapi_exception_noconnection(
  File "C:\Users\fadyz\Desktop\Personal\python-mess\SRS\.srs_algorithm\Lib\site-packages\sqlalchemy\engine\base.py", line 2439, in _handle_dbapi_exception_noconnection
    raise sqlalchemy_exception.with_traceback(exc_info[2]) from e
  File "C:\Users\fadyz\Desktop\Personal\python-mess\SRS\.srs_algorithm\Lib\site-packages\sqlalchemy\engine\base.py", line 146, in __init__
    self._dbapi_connection = engine.raw_connection()
                             ^^^^^^^^^^^^^^^^^^^^^^^
  File "C:\Users\fadyz\Desktop\Personal\python-mess\SRS\.srs_algorithm\Lib\site-packages\sqlalchemy\engine\base.py", line 3298, in raw_connection
    return self.pool.connect()
           ^^^^^^^^^^^^^^^^^^^
  File "C:\Users\fadyz\Desktop\Personal\python-mess\SRS\.srs_algorithm\Lib\site-packages\sqlalchemy\pool\base.py", line 449, in connect
    return _ConnectionFairy._checkout(self)
           ^^^^^^^^^^^^^^^^^^^^^^^^^^^^^^^^
  File "C:\Users\fadyz\Desktop\Personal\python-mess\SRS\.srs_algorithm\Lib\site-packages\sqlalchemy\pool\base.py", line 1264, in _checkout
    fairy = _ConnectionRecord.checkout(pool)
            ^^^^^^^^^^^^^^^^^^^^^^^^^^^^^^^^
  File "C:\Users\fadyz\Desktop\Personal\python-mess\SRS\.srs_algorithm\Lib\site-packages\sqlalchemy\pool\base.py", line 713, in checkout
    rec = pool._do_get()
          ^^^^^^^^^^^^^^
  File "C:\Users\fadyz\Desktop\Personal\python-mess\SRS\.srs_algorithm\Lib\site-packages\sqlalchemy\pool\impl.py", line 179, in _do_get
    with util.safe_reraise():
  File "C:\Users\fadyz\Desktop\Personal\python-mess\SRS\.srs_algorithm\Lib\site-packages\sqlalchemy\util\langhelpers.py", line 146, in __exit__
    raise exc_value.with_traceback(exc_tb)
  File "C:\Users\fadyz\Desktop\Personal\python-mess\SRS\.srs_algorithm\Lib\site-packages\sqlalchemy\pool\impl.py", line 177, in _do_get
    return self._create_connection()
           ^^^^^^^^^^^^^^^^^^^^^^^^^
  File "C:\Users\fadyz\Desktop\Personal\python-mess\SRS\.srs_algorithm\Lib\site-packages\sqlalchemy\pool\base.py", line 390, in _create_connection
    return _ConnectionRecord(self)
           ^^^^^^^^^^^^^^^^^^^^^^^
  File "C:\Users\fadyz\Desktop\Personal\python-mess\SRS\.srs_algorithm\Lib\site-packages\sqlalchemy\pool\base.py", line 675, in __init__
    self.__connect()
  File "C:\Users\fadyz\Desktop\Personal\python-mess\SRS\.srs_algorithm\Lib\site-packages\sqlalchemy\pool\base.py", line 901, in __connect
    with util.safe_reraise():
  File "C:\Users\fadyz\Desktop\Personal\python-mess\SRS\.srs_algorithm\Lib\site-packages\sqlalchemy\util\langhelpers.py", line 146, in __exit__
    raise exc_value.with_traceback(exc_tb)
  File "C:\Users\fadyz\Desktop\Personal\python-mess\SRS\.srs_algorithm\Lib\site-packages\sqlalchemy\pool\base.py", line 897, in __connect
    self.dbapi_connection = connection = pool._invoke_creator(self)
                                         ^^^^^^^^^^^^^^^^^^^^^^^^^^
  File "C:\Users\fadyz\Desktop\Personal\python-mess\SRS\.srs_algorithm\Lib\site-packages\sqlalchemy\engine\create.py", line 646, in connect
    return dialect.connect(*cargs, **cparams)
           ^^^^^^^^^^^^^^^^^^^^^^^^^^^^^^^^^^
  File "C:\Users\fadyz\Desktop\Personal\python-mess\SRS\.srs_algorithm\Lib\site-packages\sqlalchemy\engine\default.py", line 625, in connect
    return self.loaded_dbapi.connect(*cargs, **cparams)  # type: ignore[no-any-return]  # NOQA: E501
           ^^^^^^^^^^^^^^^^^^^^^^^^^^^^^^^^^^^^^^^^^^^^
  File "C:\Users\fadyz\Desktop\Personal\python-mess\SRS\.srs_algorithm\Lib\site-packages\psycopg2\__init__.py", line 122, in connect
    conn = _connect(dsn, connection_factory=connection_factory, **kwasync)
           ^^^^^^^^^^^^^^^^^^^^^^^^^^^^^^^^^^^^^^^^^^^^^^^^^^^^^^^^^^^^^^^
sqlalchemy.exc.OperationalError: (psycopg2.OperationalError) connection to server at "1.1.1.142", port 5432 failed: Connection timed out (0x0000274C/10060)
	Is the server running on that host and accepting TCP/IP connections?

(Background on this error at: https://sqlalche.me/e/20/e3q8)
